Workbook
Name Cat1a: #REF!
Name Cat2a: #REF!
Name Cat3a: #REF!
Name Liste_01: #REF!
Name Liste_07: #REF!
Name Liste_08: #REF!
Name Liste_09: #REF!
Name Note: #REF!
Name NoteApp: #REF!
Name NUcode: #REF!
Name Yes: #REF!

Sheet Data
A1: Title: | B1: Start of the academic year in Europe, 2025/2026
A2: Source: | B2: Eurydice
A3: URL: | B3: https://eurydice.eacea.ec.europa.eu/data-and-visuals/european-academic-year
A4: Copyright: | B4: European Commission, 2025
A5: Last update: | B5: 45909
A7: Country | B7: StartofYear_Period | C7: StartofYear_DecisionLevel | D7: StartofYear_Note
A8: Albania | B8: October | C8: Top-level authority
A9: Austria | B9: September/October | C9: Top-level authority | D9: Information on the decision-making level refers to universities (Universitäten) and university colleges of teacher education (Pädagogische Hochschulen). Universities of applied sciences (Fachhochschulen/Hochschulen für Angewandte Wissenschaften) and private higher education institutions have institutional autonomy to decide on the start of the academic year (generally in September or October).
A10: Belgium (Flemish Community) | B10: September | C10: Institutional autonomy | D10: The Higher Education Code specifies that the academic year should start between 1 September and 1 October. No information is available regarding the independent private sector.
A11: Belgium (French Community) | B11: September | C11: Top-level authority | D11: No information is available regarding the independent private sector.
A12: Belgium (German-speaking Community) | B12: September | C12: Top-level authority
A13: Bosnia and Herzegovina | B13: October | C13: Top-level authority
A14: Bulgaria | B14: October | C14: Institutional autonomy | D14: Some private universities start the academic year in September.
A15: Croatia | B15: September/October | C15: Institutional autonomy | D15: The Act on Higher Education and Scientific Activity specifies that the academic year spans between 1 October and 30 September of the following year. Under specific circumstances, some courses may start as early as 1 September.
A16: Cyprus | B16: September | C16: Institutional autonomy | D16: Some private higher education institutions start the academic year in October.
A17: Czechia | B17: September/October | C17: Institutional autonomy
A18: Denmark | B18: September | C18: Institutional autonomy
A19: Estonia | B19: August/September | C19: Institutional autonomy
A20: Finland | B20: August/September | C20: Institutional autonomy | D20: The official start of the academic year is in August, as defined by the top-level authority.
A21: France | B21: September/October | C21: Institutional autonomy
A22: Georgia | B22: September/October | C22: Institutional autonomy
A23: Germany | B23: October | C23: Top-level authority | D23: The decision on the start of the academic year is made by the Länder. For universities of applied sciences (Hochschulen für angewandte Wissenschaften/Fachhochschulen), the academic year typically starts in September.
A24: Greece | B24: September | C24: Institutional autonomy | D24: At ISCED 6, the top-level authority sets the official start of the academic year at 1 September, while institutional higher education institutions determine the start of teaching activities. At ISCED 7, the academic year may start in October or March.
A25: Hungary | B25: September | C25: Institutional autonomy
A26: Iceland | B26: August/September | C26: Institutional autonomy
A27: Ireland | B27: September | C27: Institutional autonomy
A28: Italy | B28: October | C28: Institutional autonomy
A29: Latvia | B29: August/September | C29: Institutional autonomy
A30: Liechtenstein | B30: September | C30: Institutional autonomy | D30: In the private sector the academic year usually starts in October.
A31: Lithuania | B31: September | C31: Institutional autonomy | D31: No information is available regarding the independent private sector.
A32: Luxembourg | B32: September | C32: Top-level authority
A33: Malta | B33: September/October | C33: Institutional autonomy | D33: For private institutions, the start of the academic year happens at different times of the year.
A34: Moldavia | B34: September | C34: Institutional autonomy
A35: Montenegro | B35: September | C35: Top-level authority
A36: Netherelands | B36: September | C36: Institutional autonomy
A37: North Macedonia | B37: September/October | C37: Institutional autonomy
A38: Norway | B38: August | C38: Institutional autonomy
A39: Poland | B39: October | C39: Top-level authority
A40: Portugal | B40: September | C40: Institutional autonomy
A41: Romania | B41: October | C41: Institutional autonomy
...

Sheet Test_Month
A1: Country code: | B1: =IF(LEN(#REF!)>0,#REF!,"") -> #REF! | G1: {=MID(CELL("filename",Test_Month!A1),FIND("]",CELL("filename",Test_Month!A1))+1,255)} -> Test_Month
A3: =mySheeetName -> #NAME?
A4: Beginning and end of school year
A5: Please specify the full name of the region/zone concerned => | B5: North | G5: Please specify the full name of the region/zone concerned => | H5: South
A6: Please specify the ISCED level(s) concerned (dropdown list) => | B6: Please specify | G6: Please specify the ISCED level(s) concerned (dropdown list) => | H6: Please specify
A7: BEGINNING of the school year for STUDENTS
A8: Initial dates may vary | B8: from | G8: Initial dates may vary | H8: from
A9: Beginning of school year | C9: 45474 | G9: Beginning of school year | I9: 45474
A10: Final dates may vary | D10: to | G10: Final dates may vary | J10: to
A11: BEGINNING of the school year for TEACHERS (NOT shown on graph)
A12: Initial dates may vary | B12: from | G12: Initial dates may vary | H12: from
A13: Beginning of school year | G13: Beginning of school year
A14: Final dates may vary | D14: to | G14: Final dates may vary | J14: to
A15: END of the school year for STUDENTS (NOT shown on graph)
A16: Initial dates may vary | B16: from | G16: Initial dates may vary | H16: from
A17: End of school year | C17: 45626 | G17: End of school year | I17: 45626
A18: Final dates may vary | D18: to | G18: Final dates may vary | J18: to
A19: END of the school year for TEACHERS (NOT shown on graph)
A20: Initial dates may vary | B20: from | G20: Initial dates may vary | H20: from
A21: End of school year | G21: End of school year
A22: Final dates may vary | D22: to | G22: Final dates may vary | J22: to | K22: =ADDRESS(ROW(),COLUMN(),4) -> K22
A24: School holiday periods (for students)
B25: =$B$5 -> North | H25: =H5 -> South
B26: =B6 -> Please specify | C26: =C6 -> 0 | D26: =D6 -> 0 | E26: =E6 -> 0 | F26: =F6 -> 0 | H26: =H6 -> Please specify | I26: =I6 -> 0 | J26: =J6 -> 0 | K26: =K6 -> 0
A27: Period 1 | G27: Period 1
A28: Initial dates may vary | B28: from | G28: Initial dates may vary | H28: from
A29: Minimum or fixed number of days | B29: from | C29: 45505 | D29: to | E29: 45505 | G29: Minimum or fixed number of days | H29: from | I29: 45505 | J29: to | K29: 45505
A30: Maximum number of days | B30: from | D30: to | G30: Maximum number of days | H30: from | J30: to
A31: Final dates may vary | D31: to | G31: Final dates may vary | J31: to
A32: Period 2 | B32: =MAX(C28:E31) -> 45505 | G32: Period 2 | H32: =MAX(I28:K31) -> 45505
A33: Initial dates may vary | B33: from | G33: Initial dates may vary | H33: from
A34: Minimum or fixed number of days | B34: from | C34: 45536 | D34: to | E34: 45537 | G34: Minimum or fixed number of days | H34: from | J34: to
A35: Maximum number of days | B35: from | D35: to | G35: Maximum number of days | H35: from | J35: to
A36: Final dates may vary | D36: to | G36: Final dates may vary | J36: to
A37: Period 3 | B37: =MAX(C33:E36) -> 45537 | G37: Period 3 | H37: =MAX(I33:K36) -> 0
A38: Initial dates may vary | B38: from | G38: Initial dates may vary | H38: from
A39: Minimum or fixed number of days | B39: from | C39: 45566 | D39: to | E39: 45567 | G39: Minimum or fixed number of days | H39: from | J39: to
A40: Maximum number of days | B40: from | D40: to | G40: Maximum number of days | H40: from | J40: to
A41: Final dates may vary | D41: to | G41: Final dates may vary | J41: to
A42: Period 4 | B42: =MAX(C38:E41) -> 45567 | G42: Period 4 | H42: =MAX(I38:K41) -> 0
...

Sheet Test_WE
A1: Country code: | B1: =IF(LEN(#REF!)>0,#REF!,"") -> #REF! | G1: {=MID(CELL("filename",Test_WE!A1),FIND("]",CELL("filename",Test_WE!A1))+1,255)} -> Test_WE
A3: =mySheeetName -> #NAME?
A4: Beginning and end of school year
A5: Please specify the full name of the region/zone concerned => | B5: PRIMARY | G5: Please specify the full name of the region/zone concerned => | H5: SECONDARY
A6: Please specify the ISCED level(s) concerned (dropdown list) => | B6: Please specify | G6: Please specify the ISCED level(s) concerned (dropdown list) => | H6: Please specify
A7: BEGINNING of the school year for STUDENTS
A8: Initial dates may vary | B8: from | G8: Initial dates may vary | H8: from
A9: Beginning of school year | C9: 45474 | G9: Beginning of school year | I9: 45474
A10: Final dates may vary | D10: to | G10: Final dates may vary | J10: to
A11: BEGINNING of the school year for TEACHERS (NOT shown on graph)
A12: Initial dates may vary | B12: from | G12: Initial dates may vary | H12: from
A13: Beginning of school year | G13: Beginning of school year
A14: Final dates may vary | D14: to | G14: Final dates may vary | J14: to
A15: END of the school year for STUDENTS (NOT shown on graph)
A16: Initial dates may vary | B16: from | G16: Initial dates may vary | H16: from
A17: End of school year | C17: 45901 | G17: End of school year | I17: 45901
A18: Final dates may vary | D18: to | G18: Final dates may vary | J18: to
A19: END of the school year for TEACHERS (NOT shown on graph)
A20: Initial dates may vary | B20: from | G20: Initial dates may vary | H20: from
A21: End of school year | G21: End of school year
A22: Final dates may vary | D22: to | G22: Final dates may vary | J22: to
A24: School holiday periods (for students)
B25: =$B$5 -> PRIMARY | H25: =H5 -> SECONDARY
B26: =B6 -> Please specify | C26: =C6 -> 0 | D26: =D6 -> 0 | E26: =E6 -> 0 | F26: =F6 -> 0 | H26: =H6 -> Please specify | I26: =I6 -> 0 | J26: =J6 -> 0 | K26: =K6 -> 0
A27: Period 1 | G27: Period 1
A28: Initial dates may vary | B28: from | G28: Initial dates may vary | H28: from
A29: Minimum or fixed number of days | B29: from | C29: 45479 | D29: to | E29: 45480 | G29: Minimum or fixed number of days | H29: from | I29: =E124+6 -> 45619 | J29: to | K29: =I29+1 -> 45620
A30: Maximum number of days | B30: from | D30: to | G30: Maximum number of days | H30: from | J30: to
A31: Final dates may vary | D31: to | G31: Final dates may vary | J31: to
A32: Period 2 | B32: =MAX(C28:E31) -> 45480 | G32: Period 2 | H32: =MAX(I28:K31) -> 45620
A33: Initial dates may vary | B33: from | G33: Initial dates may vary | H33: from
A34: Minimum or fixed number of days | B34: from | C34: =E29+6 -> 45486 | D34: to | E34: =C34+1 -> 45487 | G34: Minimum or fixed number of days | H34: from | I34: =K29+6 -> 45626 | J34: to | K34: =I34+1 -> 45627
A35: Maximum number of days | B35: from | D35: to | G35: Maximum number of days | H35: from | J35: to
A36: Final dates may vary | D36: to | G36: Final dates may vary | J36: to
A37: Period 3 | B37: =MAX(C33:E36) -> 45487 | G37: Period 3 | H37: =MAX(I33:K36) -> 45627
A38: Initial dates may vary | B38: from | G38: Initial dates may vary | H38: from
A39: Minimum or fixed number of days | B39: from | C39: =E34+6 -> 45493 | D39: to | E39: =C39+1 -> 45494 | G39: Minimum or fixed number of days | H39: from | I39: =K34+6 -> 45633 | J39: to | K39: =I39+1 -> 45634
A40: Maximum number of days | B40: from | D40: to | G40: Maximum number of days | H40: from | J40: to
A41: Final dates may vary | D41: to | G41: Final dates may vary | J41: to
A42: Period 4 | B42: =MAX(C38:E41) -> 45494 | G42: Period 4 | H42: =MAX(I38:K41) -> 45634
...

Sheet DaB
A1: no | G1: 365 | AB1: 365 | EU1: 365
E2: Period 1 | G2: =G7 -> #REF! | L2: Period 2 | N2: =N7 -> #REF! | S2: Period 3 | U2: =U7 -> #REF! | Z2: Period 4 | AB2: =AB7 -> #REF! | AG2: Period 5 | AI2: =AI7 -> #REF! | AN2: Period 6 | AP2: =AP7 -> #REF! | AU2: Period 7 | AW2: =AW7 -> #REF! | BB2: Period 8 | BD2: =BD7 -> #REF! | BI2: Period 9 | BK2: =BK7 -> #REF! | BP2: Period 10 | BR2: =BR7 -> #REF! | BW2: Period 11 | BY2: =BY7 -> #REF! | CD2: Period 12 | CF2: =CF7 -> #REF! | CK2: Period 13 | CM2: =CM7 -> #REF! | CR2: Period 14 | CT2: =CT7 -> #REF! | CY2: Period 15 | DA2: =DA7 -> #REF! | DF2: Period 16 | DH2: =DH7 -> #REF! | DM2: Period 17 | DO2: =DO7 -> #REF! | DT2: Period 18 | DV2: =DV7 -> #REF! | EA2: Period 19 | EC2: =EC7 -> #REF! | EH2: Period 20 | EJ2: =EJ7 -> #REF! | ES2: =C2 -> 0 | ET2: Students BEGINNING | FA2: Students END | FH2: Teachers BEGINNING | FO2: Teachers END
B3: Country_code | C3: Overview_Regional_calendar | D3: Level of education | E3: =$ET$3 -> Period_name | F3: =#REF! -> #REF! | G3: Min from | H3: Min to | I3: Max from | J3: Max to | K3: =#REF! -> #REF! | L3: =$ET$3 -> Period_name | M3: =#REF! -> #REF! | N3: Min from | O3: Min to | P3: Max from | Q3: Max to | R3: =#REF! -> #REF! | S3: =$ET$3 -> Period_name | T3: =#REF! -> #REF! | U3: Min from | V3: Min to | W3: Max from | X3: Max to | Y3: =#REF! -> #REF! | Z3: =$ET$3 -> Period_name | AA3: =#REF! -> #REF! | AB3: Min from | AC3: Min to | AD3: Max from | AE3: Max to | AF3: =#REF! -> #REF! | AG3: =$ET$3 -> Period_name | AH3: =#REF! -> #REF! | AI3: Min from | AJ3: Min to | AK3: Max from | AL3: Max to | AM3: =#REF! -> #REF! | AN3: =$ET$3 -> Period_name | AO3: =#REF! -> #REF! | AP3: Min from | AQ3: Min to | AR3: Max from | AS3: Max to | AT3: =#REF! -> #REF! | AU3: =$ET$3 -> Period_name | AV3: =#REF! -> #REF! | AW3: Min from | AX3: Min to | AY3: Max from | AZ3: Max to | BA3: =#REF! -> #REF! | BB3: =$ET$3 -> Period_name | BC3: =#REF! -> #REF! | BD3: Min from | BE3: Min to | BF3: Max from | BG3: Max to | BH3: =#REF! -> #REF! | BI3: =$ET$3 -> Period_name | BJ3: =#REF! -> #REF! | BK3: Min from | BL3: Min to | BM3: Max from | BN3: Max to | BO3: =#REF! -> #REF! | BP3: =$ET$3 -> Period_name | BQ3: =#REF! -> #REF! | BR3: Min from | BS3: Min to | BT3: Max from | BU3: Max to | BV3: =#REF! -> #REF! | BW3: =$ET$3 -> Period_name | BX3: =#REF! -> #REF! | BY3: Min from | BZ3: Min to | CA3: Max from | CB3: Max to | CC3: =#REF! -> #REF! | CD3: =$ET$3 -> Period_name | CE3: =#REF! -> #REF! | CF3: Min from | CG3: Min to | CH3: Max from | CI3: Max to | CJ3: =#REF! -> #REF! | CK3: =$ET$3 -> Period_name | CL3: =#REF! -> #REF! | CM3: Min from | CN3: Min to | CO3: Max from | CP3: Max to | CQ3: =#REF! -> #REF! | CR3: =$ET$3 -> Period_name | CS3: =#REF! -> #REF! | CT3: Min from | CU3: Min to | CV3: Max from | CW3: Max to | CX3: =#REF! -> #REF! | CY3: =$ET$3 -> Period_name | CZ3: =#REF! -> #REF! | DA3: Min from | DB3: Min to | DC3: Max from | DD3: Max to | DE3: =#REF! -> #REF! | DF3: =$ET$3 -> Period_name | DG3: =#REF! -> #REF! | DH3: Min from | DI3: Min to | DJ3: Max from | DK3: Max to | DL3: =#REF! -> #REF! | DM3: =$ET$3 -> Period_name | DN3: =#REF! -> #REF! | DO3: Min from | DP3: Min to | DQ3: Max from | DR3: Max to | DS3: =#REF! -> #REF! | DT3: =$ET$3 -> Period_name | DU3: =#REF! -> #REF! | DV3: Min from | DW3: Min to | DX3: Max from | DY3: Max to | DZ3: =#REF! -> #REF! | EA3: =$ET$3 -> Period_name | EB3: =#REF! -> #REF! | EC3: Min from | ED3: Min to | EE3: Max from | EF3: Max to | EG3: =#REF! -> #REF! | EH3: =$ET$3 -> Period_name | EI3: =#REF! -> #REF! | EJ3: Min from | EK3: Min to | EL3: Max from | EM3: Max to | EN3: =#REF! -> #REF! | ES3: =C3 -> Overview_Regional_calendar | ET3: Period_name | EU3: Initial dates may vary | EV3: Beginning of school year for students | EZ3: Final dates may vary | FA3: =$ET$3 -> Period_name | FB3: Initial dates may vary | FC3: End of school year | FG3: Final dates may vary | FH3: =$ET$3 -> Period_name | FI3: =EU3 -> Initial dates may vary | FJ3: Beginning of school year for teachers | FN3: =EZ3 -> Final dates may vary | FO3: =$ET$3 -> Period_name | FP3: =FB3 -> Initial dates may vary | FQ3: End of school year | FU3: Final dates may vary
A4: =#REF! -> #REF! | B4: =B3 -> Country_code | C4: {=MID(CELL("filename",#REF!),FIND("]",CELL("filename",#REF!))+1,255)} -> #REF! | D4: =#REF! -> #REF! | E4: =#REF! -> #REF! | F4: =IF(#REF!=0,"-",#REF!) -> #REF! | G4: =IF(#REF!=0,"-",#REF!) -> #REF! | H4: =IF(#REF!=0,"-",#REF!) -> #REF! | I4: =IF(#REF!=0,"-",#REF!) -> #REF! | J4: =IF(#REF!=0,"-",#REF!) -> #REF! | K4: =IF(#REF!=0,"-",#REF!) -> #REF! | L4: Period 2 | M4: =IF(#REF!=0,"-",#REF!) -> #REF! | N4: =IF(#REF!=0,"-",#REF!) -> #REF! | O4: =IF(#REF!=0,"-",#REF!) -> #REF! | P4: =IF(#REF!=0,"-",#REF!) -> #REF! | Q4: =IF(#REF!=0,"-",#REF!) -> #REF! | R4: =IF(#REF!=0,"-",#REF!) -> #REF! | S4: Period 3 | T4: =IF(#REF!=0,"-",#REF!) -> #REF! | U4: =IF(#REF!=0,"-",#REF!) -> #REF! | V4: =IF(#REF!=0,"-",#REF!) -> #REF! | W4: =IF(#REF!=0,"-",#REF!) -> #REF! | X4: =IF(#REF!=0,"-",#REF!) -> #REF! | Y4: =IF(#REF!=0,"-",#REF!) -> #REF! | Z4: Period 4 | AA4: =IF(#REF!=0,"-",#REF!) -> #REF! | AB4: =IF(#REF!=0,"-",#REF!) -> #REF! | AC4: =IF(#REF!=0,"-",#REF!) -> #REF! | AD4: =IF(#REF!=0,"-",#REF!) -> #REF! | AE4: =IF(#REF!=0,"-",#REF!) -> #REF! | AF4: =IF(#REF!=0,"-",#REF!) -> #REF! | AG4: Period 5 | AH4: =IF(#REF!=0,"-",#REF!) -> #REF! | AI4: =IF(#REF!=0,"-",#REF!) -> #REF! | AJ4: =IF(#REF!=0,"-",#REF!) -> #REF! | AK4: =IF(#REF!=0,"-",#REF!) -> #REF! | AL4: =IF(#REF!=0,"-",#REF!) -> #REF! | AM4: =IF(#REF!=0,"-",#REF!) -> #REF! | AN4: Period 6 | AO4: =IF(#REF!=0,"-",#REF!) -> #REF! | AP4: =IF(#REF!=0,"-",#REF!) -> #REF! | AQ4: =IF(#REF!=0,"-",#REF!) -> #REF! | AR4: =IF(#REF!=0,"-",#REF!) -> #REF! | AS4: =IF(#REF!=0,"-",#REF!) -> #REF! | AT4: =IF(#REF!=0,"-",#REF!) -> #REF! | AU4: Period 7 | AV4: =IF(#REF!=0,"-",#REF!) -> #REF! | AW4: =IF(#REF!=0,"-",#REF!) -> #REF! | AX4: =IF(#REF!=0,"-",#REF!) -> #REF! | AY4: =IF(#REF!=0,"-",#REF!) -> #REF! | AZ4: =IF(#REF!=0,"-",#REF!) -> #REF! | BA4: =IF(#REF!=0,"-",#REF!) -> #REF! | BB4: Period 8 | BC4: =IF(#REF!=0,"-",#REF!) -> #REF! | BD4: =IF(#REF!=0,"-",#REF!) -> #REF! | BE4: =IF(#REF!=0,"-",#REF!) -> #REF! | BF4: =IF(#REF!=0,"-",#REF!) -> #REF! | BG4: =IF(#REF!=0,"-",#REF!) -> #REF! | BH4: =IF(#REF!=0,"-",#REF!) -> #REF! | BI4: Period 9 | BJ4: =IF(#REF!=0,"-",#REF!) -> #REF! | BK4: =IF(#REF!=0,"-",#REF!) -> #REF! | BL4: =IF(#REF!=0,"-",#REF!) -> #REF! | BM4: =IF(#REF!=0,"-",#REF!) -> #REF! | BN4: =IF(#REF!=0,"-",#REF!) -> #REF! | BO4: =IF(#REF!=0,"-",#REF!) -> #REF! | BP4: Period 10 | BQ4: =IF(#REF!=0,"-",#REF!) -> #REF! | BR4: =IF(#REF!="-",0,#REF!) -> #REF! | BS4: =IF(#REF!=0,"-",#REF!) -> #REF! | BT4: =IF(#REF!=0,"-",#REF!) -> #REF! | BU4: =IF(#REF!=0,"-",#REF!) -> #REF! | BV4: =IF(#REF!=0,"-",#REF!) -> #REF! | BW4: Period 11 | BX4: =IF(#REF!=0,"-",#REF!) -> #REF! | BY4: =IF(#REF!=0,"-",#REF!) -> #REF! | BZ4: =IF(#REF!=0,"-",#REF!) -> #REF! | CA4: =IF(#REF!=0,"-",#REF!) -> #REF! | CB4: =IF(#REF!=0,"-",#REF!) -> #REF! | CC4: =IF(#REF!=0,"-",#REF!) -> #REF! | CD4: Period 12 | CE4: =IF(#REF!=0,"-",#REF!) -> #REF! | CF4: =IF(#REF!=0,"-",#REF!) -> #REF! | CG4: =IF(#REF!=0,"-",#REF!) -> #REF! | CH4: =IF(#REF!=0,"-",#REF!) -> #REF! | CI4: =IF(#REF!=0,"-",#REF!) -> #REF! | CJ4: =IF(#REF!=0,"-",#REF!) -> #REF! | CK4: Period 13 | CL4: =IF(#REF!=0,"-",#REF!) -> #REF! | CM4: =IF(#REF!=0,"-",#REF!) -> #REF! | CN4: =IF(#REF!=0,"-",#REF!) -> #REF! | CO4: =IF(#REF!=0,"-",#REF!) -> #REF! | CP4: =IF(#REF!=0,"-",#REF!) -> #REF! | CQ4: =IF(#REF!=0,"-",#REF!) -> #REF! | CR4: Period 14 | CS4: =IF(#REF!=0,"-",#REF!) -> #REF! | CT4: =IF(#REF!=0,"-",#REF!) -> #REF! | CU4: =IF(#REF!=0,"-",#REF!) -> #REF! | CV4: =IF(#REF!=0,"-",#REF!) -> #REF! | CW4: =IF(#REF!=0,"-",#REF!) -> #REF! | CX4: =IF(#REF!=0,"-",#REF!) -> #REF! | CY4: Period 15 | CZ4: =IF(#REF!=0,"-",#REF!) -> #REF! | DA4: =IF(#REF!=0,"-",#REF!) -> #REF! | DB4: =IF(#REF!=0,"-",#REF!) -> #REF! | DC4: =IF(#REF!=0,"-",#REF!) -> #REF! | DD4: =IF(#REF!=0,"-",#REF!) -> #REF! | DE4: =IF(#REF!=0,"-",#REF!) -> #REF! | DF4: Period 16 | DG4: =IF(#REF!=0,"-",#REF!) -> #REF! | DH4: =IF(#REF!=0,"-",#REF!) -> #REF! | DI4: =IF(#REF!=0,"-",#REF!) -> #REF! | DJ4: =IF(#REF!=0,"-",#REF!) -> #REF! | DK4: =IF(#REF!=0,"-",#REF!) -> #REF! | DL4: =IF(#REF!=0,"-",#REF!) -> #REF! | DM4: Period 17 | DN4: =IF(#REF!=0,"-",#REF!) -> #REF! | DO4: =IF(#REF!=0,"-",#REF!) -> #REF! | DP4: =IF(#REF!=0,"-",#REF!) -> #REF! | DQ4: =IF(#REF!=0,"-",#REF!) -> #REF! | DR4: =IF(#REF!=0,"-",#REF!) -> #REF! | DS4: =IF(#REF!=0,"-",#REF!) -> #REF! | DT4: Period 18 | DU4: =IF(#REF!=0,"-",#REF!) -> #REF! | DV4: =IF(#REF!=0,"-",#REF!) -> #REF! | DW4: =IF(#REF!=0,"-",#REF!) -> #REF! | DX4: =IF(#REF!=0,"-",#REF!) -> #REF! | DY4: =IF(#REF!=0,"-",#REF!) -> #REF! | DZ4: =IF(#REF!=0,"-",#REF!) -> #REF! | EA4: Period 19 | EB4: =IF(#REF!=0,"-",#REF!) -> #REF! | EC4: =IF(#REF!=0,"-",#REF!) -> #REF! | ED4: =IF(#REF!=0,"-",#REF!) -> #REF! | EE4: =IF(#REF!=0,"-",#REF!) -> #REF! | EF4: =IF(#REF!=0,"-",#REF!) -> #REF! | EG4: =IF(#REF!=0,"-",#REF!) -> #REF! | EH4: Period 20 | EI4: =IF(#REF!=0,"-",#REF!) -> #REF! | EJ4: =IF(#REF!=0,"-",#REF!) -> #REF! | EK4: =IF(#REF!=0,"-",#REF!) -> #REF! | EL4: =IF(#REF!=0,"-",#REF!) -> #REF! | EM4: =IF(#REF!=0,"-",#REF!) -> #REF! | EN4: =IF(#REF!=0,"-",#REF!) -> #REF! | ES4: =C4 -> #REF! | ET4: BEGINNING of the school year for STUDENTS | EU4: =IF(#REF!=0,"",#REF!) -> #REF! | EV4: =IF(OR(#REF!=0,#REF!=""),"",#REF!) -> #REF! | EW4: =EV4 -> #REF! | EZ4: =IF(#REF!=0,"",#REF!) -> #REF! | FA4: END of the school year for STUDENTS (NOT shown on graph) | FB4: =IF(#REF!=0,"",#REF!) -> #REF! | FC4: =IF(OR(#REF!=0,#REF!=""),"",#REF!) -> #REF! | FD4: =FC4 -> #REF! | FE4: - | FF4: - | FG4: =IF(#REF!=0,"-",#REF!) -> #REF! | FH4: BEGINNING of the school year for TEACHERS (NOT shown on graph) | FI4: =IF(#REF!=0,"-",#REF!) -> #REF! | FJ4: =IF(#REF!=0,"-",#REF!) -> #REF! | FK4: =IF(#REF!=0,"-",#REF!) -> #REF! | FL4: - | FM4: - | FN4: =IF(#REF!=0,"-",#REF!) -> #REF! | FO4: END of the school year for TEACHERS (NOT shown on graph) | FP4: =IF(#REF!=0,"-",#REF!) -> #REF! | FQ4: =IF(#REF!=0,"-",#REF!) -> #REF! | FR4: =IF(#REF!=0,"-",#REF!) -> #REF! | FS4: - | FT4: - | FU4: =IF(#REF!=0,"-",#REF!) -> #REF!
A5: =#REF! -> #REF! | B5: =B4 -> Country_code | C5: {=MID(CELL("filename",#REF!),FIND("]",CELL("filename",#REF!))+1,255)} -> #REF! | D5: =#REF! -> #REF! | E5: =#REF! -> #REF! | F5: =IF(#REF!=0,"-",#REF!) -> #REF! | G5: =IF(#REF!=0,"-",#REF!) -> #REF! | H5: =IF(#REF!=0,"-",#REF!) -> #REF! | I5: =IF(#REF!=0,"-",#REF!) -> #REF! | J5: =IF(#REF!=0,"-",#REF!) -> #REF! | K5: =IF(#REF!=0,"-",#REF!) -> #REF! | L5: Period 2 | M5: =IF(#REF!=0,"-",#REF!) -> #REF! | N5: =IF(#REF!=0,"-",#REF!) -> #REF! | O5: =IF(#REF!=0,"-",#REF!) -> #REF! | P5: =IF(#REF!=0,"-",#REF!) -> #REF! | Q5: =IF(#REF!=0,"-",#REF!) -> #REF! | R5: =IF(#REF!=0,"-",#REF!) -> #REF! | S5: Period 3 | T5: =IF(#REF!=0,"-",#REF!) -> #REF! | U5: =IF(#REF!=0,"-",#REF!) -> #REF! | V5: =IF(#REF!=0,"-",#REF!) -> #REF! | W5: =IF(#REF!=0,"-",#REF!) -> #REF! | X5: =IF(#REF!=0,"-",#REF!) -> #REF! | Y5: =IF(#REF!=0,"-",#REF!) -> #REF! | Z5: Period 4 | AA5: =IF(#REF!=0,"-",#REF!) -> #REF! | AB5: =IF(#REF!=0,"-",#REF!) -> #REF! | AC5: =IF(#REF!=0,"-",#REF!) -> #REF! | AD5: =IF(#REF!=0,"-",#REF!) -> #REF! | AE5: =IF(#REF!=0,"-",#REF!) -> #REF! | AF5: =IF(#REF!=0,"-",#REF!) -> #REF! | AG5: Period 5 | AH5: =IF(#REF!=0,"-",#REF!) -> #REF! | AI5: =IF(#REF!=0,"-",#REF!) -> #REF! | AJ5: =IF(#REF!=0,"-",#REF!) -> #REF! | AK5: =IF(#REF!=0,"-",#REF!) -> #REF! | AL5: =IF(#REF!=0,"-",#REF!) -> #REF! | AM5: =IF(#REF!=0,"-",#REF!) -> #REF! | AN5: Period 6 | AO5: =IF(#REF!=0,"-",#REF!) -> #REF! | AP5: =IF(#REF!=0,"-",#REF!) -> #REF! | AQ5: =IF(#REF!=0,"-",#REF!) -> #REF! | AR5: =IF(#REF!=0,"-",#REF!) -> #REF! | AS5: =IF(#REF!=0,"-",#REF!) -> #REF! | AT5: =IF(#REF!=0,"-",#REF!) -> #REF! | AU5: Period 7 | AV5: =IF(#REF!=0,"-",#REF!) -> #REF! | AW5: =IF(#REF!=0,"-",#REF!) -> #REF! | AX5: =IF(#REF!=0,"-",#REF!) -> #REF! | AY5: =IF(#REF!=0,"-",#REF!) -> #REF! | AZ5: =IF(#REF!=0,"-",#REF!) -> #REF! | BA5: =IF(#REF!=0,"-",#REF!) -> #REF! | BB5: Period 8 | BC5: =IF(#REF!=0,"-",#REF!) -> #REF! | BD5: =IF(#REF!=0,"-",#REF!) -> #REF! | BE5: =IF(#REF!=0,"-",#REF!) -> #REF! | BF5: =IF(#REF!=0,"-",#REF!) -> #REF! | BG5: =IF(#REF!=0,"-",#REF!) -> #REF! | BH5: =IF(#REF!=0,"-",#REF!) -> #REF! | BI5: Period 9 | BJ5: =IF(#REF!=0,"-",#REF!) -> #REF! | BK5: =IF(#REF!=0,"-",#REF!) -> #REF! | BL5: =IF(#REF!=0,"-",#REF!) -> #REF! | BM5: =IF(#REF!=0,"-",#REF!) -> #REF! | BN5: =IF(#REF!=0,"-",#REF!) -> #REF! | BO5: =IF(#REF!=0,"-",#REF!) -> #REF! | BP5: Period 10 | BQ5: =IF(#REF!=0,"-",#REF!) -> #REF! | BR5: =IF(#REF!="-",0,#REF!) -> #REF! | BS5: =IF(#REF!=0,"-",#REF!) -> #REF! | BT5: =IF(#REF!=0,"-",#REF!) -> #REF! | BU5: =IF(#REF!=0,"-",#REF!) -> #REF! | BV5: =IF(#REF!=0,"-",#REF!) -> #REF! | BW5: Period 11 | BX5: =IF(#REF!=0,"-",#REF!) -> #REF! | BY5: =IF(#REF!=0,"-",#REF!) -> #REF! | BZ5: =IF(#REF!=0,"-",#REF!) -> #REF! | CA5: =IF(#REF!=0,"-",#REF!) -> #REF! | CB5: =IF(#REF!=0,"-",#REF!) -> #REF! | CC5: =IF(#REF!=0,"-",#REF!) -> #REF! | CD5: Period 12 | CE5: =IF(#REF!=0,"-",#REF!) -> #REF! | CF5: =IF(#REF!=0,"-",#REF!) -> #REF! | CG5: =IF(#REF!=0,"-",#REF!) -> #REF! | CH5: =IF(#REF!=0,"-",#REF!) -> #REF! | CI5: =IF(#REF!=0,"-",#REF!) -> #REF! | CJ5: =IF(#REF!=0,"-",#REF!) -> #REF! | CK5: Period 13 | CL5: =IF(#REF!=0,"-",#REF!) -> #REF! | CM5: =IF(#REF!=0,"-",#REF!) -> #REF! | CN5: =IF(#REF!=0,"-",#REF!) -> #REF! | CO5: =IF(#REF!=0,"-",#REF!) -> #REF! | CP5: =IF(#REF!=0,"-",#REF!) -> #REF! | CQ5: =IF(#REF!=0,"-",#REF!) -> #REF! | CR5: Period 14 | CS5: =IF(#REF!=0,"-",#REF!) -> #REF! | CT5: =IF(#REF!=0,"-",#REF!) -> #REF! | CU5: =IF(#REF!=0,"-",#REF!) -> #REF! | CV5: =IF(#REF!=0,"-",#REF!) -> #REF! | CW5: =IF(#REF!=0,"-",#REF!) -> #REF! | CX5: =IF(#REF!=0,"-",#REF!) -> #REF! | CY5: Period 15 | CZ5: =IF(#REF!=0,"-",#REF!) -> #REF! | DA5: =IF(#REF!=0,"-",#REF!) -> #REF! | DB5: =IF(#REF!=0,"-",#REF!) -> #REF! | DC5: =IF(#REF!=0,"-",#REF!) -> #REF! | DD5: =IF(#REF!=0,"-",#REF!) -> #REF! | DE5: =IF(#REF!=0,"-",#REF!) -> #REF! | DF5: Period 16 | DG5: =IF(#REF!=0,"-",#REF!) -> #REF! | DH5: =IF(#REF!=0,"-",#REF!) -> #REF! | DI5: =IF(#REF!=0,"-",#REF!) -> #REF! | DJ5: =IF(#REF!=0,"-",#REF!) -> #REF! | DK5: =IF(#REF!=0,"-",#REF!) -> #REF! | DL5: =IF(#REF!=0,"-",#REF!) -> #REF! | DM5: Period 17 | DN5: =IF(#REF!=0,"-",#REF!) -> #REF! | DO5: =IF(#REF!=0,"-",#REF!) -> #REF! | DP5: =IF(#REF!=0,"-",#REF!) -> #REF! | DQ5: =IF(#REF!=0,"-",#REF!) -> #REF! | DR5: =IF(#REF!=0,"-",#REF!) -> #REF! | DS5: =IF(#REF!=0,"-",#REF!) -> #REF! | DT5: Period 18 | DU5: =IF(#REF!=0,"-",#REF!) -> #REF! | DV5: =IF(#REF!=0,"-",#REF!) -> #REF! | DW5: =IF(#REF!=0,"-",#REF!) -> #REF! | DX5: =IF(#REF!=0,"-",#REF!) -> #REF! | DY5: =IF(#REF!=0,"-",#REF!) -> #REF! | DZ5: =IF(#REF!=0,"-",#REF!) -> #REF! | EA5: Period 19 | EB5: =IF(#REF!=0,"-",#REF!) -> #REF! | EC5: =IF(#REF!=0,"-",#REF!) -> #REF! | ED5: =IF(#REF!=0,"-",#REF!) -> #REF! | EE5: =IF(#REF!=0,"-",#REF!) -> #REF! | EF5: =IF(#REF!=0,"-",#REF!) -> #REF! | EG5: =IF(#REF!=0,"-",#REF!) -> #REF! | EH5: Period 20 | EI5: =IF(#REF!=0,"-",#REF!) -> #REF! | EJ5: =IF(#REF!=0,"-",#REF!) -> #REF! | EK5: =IF(#REF!=0,"-",#REF!) -> #REF! | EL5: =IF(#REF!=0,"-",#REF!) -> #REF! | EM5: =IF(#REF!=0,"-",#REF!) -> #REF! | EN5: =IF(#REF!=0,"-",#REF!) -> #REF! | ES5: =C5 -> #REF! | ET5: BEGINNING of the school year for STUDENTS | EU5: =IF(#REF!=0,"",#REF!) -> #REF! | EV5: =IF(OR(#REF!=0,#REF!=""),"",#REF!) -> #REF! | EW5: =EV5 -> #REF! | EZ5: =IF(#REF!=0,"",#REF!) -> #REF! | FA5: END of the school year for STUDENTS (NOT shown on graph) | FB5: =IF(#REF!=0,"",#REF!) -> #REF! | FC5: =IF(OR(#REF!=0,#REF!=""),"",#REF!) -> #REF! | FD5: =FC5 -> #REF! | FE5: - | FF5: - | FG5: =IF(#REF!=0,"-",#REF!) -> #REF! | FH5: BEGINNING of the school year for TEACHERS (NOT shown on graph) | FI5: =IF(#REF!=0,"-",#REF!) -> #REF! | FJ5: =IF(#REF!=0,"-",#REF!) -> #REF! | FK5: =IF(#REF!=0,"-",#REF!) -> #REF! | FL5: - | FM5: - | FN5: =IF(#REF!=0,"-",#REF!) -> #REF! | FO5: END of the school year for TEACHERS (NOT shown on graph) | FP5: =IF(#REF!=0,"-",#REF!) -> #REF! | FQ5: =IF(#REF!=0,"-",#REF!) -> #REF! | FR5: =IF(#REF!=0,"-",#REF!) -> #REF! | FS5: - | FT5: - | FU5: =IF(#REF!=0,"-",#REF!) -> #REF!
A6: =#REF! -> #REF! | B6: =B5 -> Country_code | C6: {=MID(CELL("filename",#REF!),FIND("]",CELL("filename",#REF!))+1,255)} -> #REF! | D6: =#REF! -> #REF! | E6: =#REF! -> #REF! | F6: =IF(#REF!=0,"-",#REF!) -> #REF! | G6: =IF(#REF!=0,"-",#REF!) -> #REF! | H6: =IF(#REF!=0,"-",#REF!) -> #REF! | I6: =IF(#REF!=0,"-",#REF!) -> #REF! | J6: =IF(#REF!=0,"-",#REF!) -> #REF! | K6: =IF(#REF!=0,"-",#REF!) -> #REF! | L6: Period 2 | M6: =IF(#REF!=0,"-",#REF!) -> #REF! | N6: =IF(#REF!=0,"-",#REF!) -> #REF! | O6: =IF(#REF!=0,"-",#REF!) -> #REF! | P6: =IF(#REF!=0,"-",#REF!) -> #REF! | Q6: =IF(#REF!=0,"-",#REF!) -> #REF! | R6: =IF(#REF!=0,"-",#REF!) -> #REF! | S6: Period 3 | T6: =IF(#REF!=0,"-",#REF!) -> #REF! | U6: =IF(#REF!=0,"-",#REF!) -> #REF! | V6: =IF(#REF!=0,"-",#REF!) -> #REF! | W6: =IF(#REF!=0,"-",#REF!) -> #REF! | X6: =IF(#REF!=0,"-",#REF!) -> #REF! | Y6: =IF(#REF!=0,"-",#REF!) -> #REF! | Z6: Period 4 | AA6: =IF(#REF!=0,"-",#REF!) -> #REF! | AB6: =IF(#REF!=0,"-",#REF!) -> #REF! | AC6: =IF(#REF!=0,"-",#REF!) -> #REF! | AD6: =IF(#REF!=0,"-",#REF!) -> #REF! | AE6: =IF(#REF!=0,"-",#REF!) -> #REF! | AF6: =IF(#REF!=0,"-",#REF!) -> #REF! | AG6: Period 5 | AH6: =IF(#REF!=0,"-",#REF!) -> #REF! | AI6: =IF(#REF!=0,"-",#REF!) -> #REF! | AJ6: =IF(#REF!=0,"-",#REF!) -> #REF! | AK6: =IF(#REF!=0,"-",#REF!) -> #REF! | AL6: =IF(#REF!=0,"-",#REF!) -> #REF! | AM6: =IF(#REF!=0,"-",#REF!) -> #REF! | AN6: Period 6 | AO6: =IF(#REF!=0,"-",#REF!) -> #REF! | AP6: =IF(#REF!=0,"-",#REF!) -> #REF! | AQ6: =IF(#REF!=0,"-",#REF!) -> #REF! | AR6: =IF(#REF!=0,"-",#REF!) -> #REF! | AS6: =IF(#REF!=0,"-",#REF!) -> #REF! | AT6: =IF(#REF!=0,"-",#REF!) -> #REF! | AU6: Period 7 | AV6: =IF(#REF!=0,"-",#REF!) -> #REF! | AW6: =IF(#REF!=0,"-",#REF!) -> #REF! | AX6: =IF(#REF!=0,"-",#REF!) -> #REF! | AY6: =IF(#REF!=0,"-",#REF!) -> #REF! | AZ6: =IF(#REF!=0,"-",#REF!) -> #REF! | BA6: =IF(#REF!=0,"-",#REF!) -> #REF! | BB6: Period 8 | BC6: =IF(#REF!=0,"-",#REF!) -> #REF! | BD6: =IF(#REF!=0,"-",#REF!) -> #REF! | BE6: =IF(#REF!=0,"-",#REF!) -> #REF! | BF6: =IF(#REF!=0,"-",#REF!) -> #REF! | BG6: =IF(#REF!=0,"-",#REF!) -> #REF! | BH6: =IF(#REF!=0,"-",#REF!) -> #REF! | BI6: Period 9 | BJ6: =IF(#REF!=0,"-",#REF!) -> #REF! | BK6: =IF(#REF!=0,"-",#REF!) -> #REF! | BL6: =IF(#REF!=0,"-",#REF!) -> #REF! | BM6: =IF(#REF!=0,"-",#REF!) -> #REF! | BN6: =IF(#REF!=0,"-",#REF!) -> #REF! | BO6: =IF(#REF!=0,"-",#REF!) -> #REF! | BP6: Period 10 | BQ6: =IF(#REF!=0,"-",#REF!) -> #REF! | BR6: =IF(#REF!="-",0,#REF!) -> #REF! | BS6: =IF(#REF!=0,"-",#REF!) -> #REF! | BT6: =IF(#REF!=0,"-",#REF!) -> #REF! | BU6: =IF(#REF!=0,"-",#REF!) -> #REF! | BV6: =IF(#REF!=0,"-",#REF!) -> #REF! | BW6: Period 11 | BX6: =IF(#REF!=0,"-",#REF!) -> #REF! | BY6: =IF(#REF!=0,"-",#REF!) -> #REF! | BZ6: =IF(#REF!=0,"-",#REF!) -> #REF! | CA6: =IF(#REF!=0,"-",#REF!) -> #REF! | CB6: =IF(#REF!=0,"-",#REF!) -> #REF! | CC6: =IF(#REF!=0,"-",#REF!) -> #REF! | CD6: Period 12 | CE6: =IF(#REF!=0,"-",#REF!) -> #REF! | CF6: =IF(#REF!=0,"-",#REF!) -> #REF! | CG6: =IF(#REF!=0,"-",#REF!) -> #REF! | CH6: =IF(#REF!=0,"-",#REF!) -> #REF! | CI6: =IF(#REF!=0,"-",#REF!) -> #REF! | CJ6: =IF(#REF!=0,"-",#REF!) -> #REF! | CK6: Period 13 | CL6: =IF(#REF!=0,"-",#REF!) -> #REF! | CM6: =IF(#REF!=0,"-",#REF!) -> #REF! | CN6: =IF(#REF!=0,"-",#REF!) -> #REF! | CO6: =IF(#REF!=0,"-",#REF!) -> #REF! | CP6: =IF(#REF!=0,"-",#REF!) -> #REF! | CQ6: =IF(#REF!=0,"-",#REF!) -> #REF! | CR6: Period 14 | CS6: =IF(#REF!=0,"-",#REF!) -> #REF! | CT6: =IF(#REF!=0,"-",#REF!) -> #REF! | CU6: =IF(#REF!=0,"-",#REF!) -> #REF! | CV6: =IF(#REF!=0,"-",#REF!) -> #REF! | CW6: =IF(#REF!=0,"-",#REF!) -> #REF! | CX6: =IF(#REF!=0,"-",#REF!) -> #REF! | CY6: Period 15 | CZ6: =IF(#REF!=0,"-",#REF!) -> #REF! | DA6: =IF(#REF!=0,"-",#REF!) -> #REF! | DB6: =IF(#REF!=0,"-",#REF!) -> #REF! | DC6: =IF(#REF!=0,"-",#REF!) -> #REF! | DD6: =IF(#REF!=0,"-",#REF!) -> #REF! | DE6: =IF(#REF!=0,"-",#REF!) -> #REF! | DF6: Period 16 | DG6: =IF(#REF!=0,"-",#REF!) -> #REF! | DH6: =IF(#REF!=0,"-",#REF!) -> #REF! | DI6: =IF(#REF!=0,"-",#REF!) -> #REF! | DJ6: =IF(#REF!=0,"-",#REF!) -> #REF! | DK6: =IF(#REF!=0,"-",#REF!) -> #REF! | DL6: =IF(#REF!=0,"-",#REF!) -> #REF! | DM6: Period 17 | DN6: =IF(#REF!=0,"-",#REF!) -> #REF! | DO6: =IF(#REF!=0,"-",#REF!) -> #REF! | DP6: =IF(#REF!=0,"-",#REF!) -> #REF! | DQ6: =IF(#REF!=0,"-",#REF!) -> #REF! | DR6: =IF(#REF!=0,"-",#REF!) -> #REF! | DS6: =IF(#REF!=0,"-",#REF!) -> #REF! | DT6: Period 18 | DU6: =IF(#REF!=0,"-",#REF!) -> #REF! | DV6: =IF(#REF!=0,"-",#REF!) -> #REF! | DW6: =IF(#REF!=0,"-",#REF!) -> #REF! | DX6: =IF(#REF!=0,"-",#REF!) -> #REF! | DY6: =IF(#REF!=0,"-",#REF!) -> #REF! | DZ6: =IF(#REF!=0,"-",#REF!) -> #REF! | EA6: Period 19 | EB6: =IF(#REF!=0,"-",#REF!) -> #REF! | EC6: =IF(#REF!=0,"-",#REF!) -> #REF! | ED6: =IF(#REF!=0,"-",#REF!) -> #REF! | EE6: =IF(#REF!=0,"-",#REF!) -> #REF! | EF6: =IF(#REF!=0,"-",#REF!) -> #REF! | EG6: =IF(#REF!=0,"-",#REF!) -> #REF! | EH6: Period 20 | EI6: =IF(#REF!=0,"-",#REF!) -> #REF! | EJ6: =IF(#REF!=0,"-",#REF!) -> #REF! | EK6: =IF(#REF!=0,"-",#REF!) -> #REF! | EL6: =IF(#REF!=0,"-",#REF!) -> #REF! | EM6: =IF(#REF!=0,"-",#REF!) -> #REF! | EN6: =IF(#REF!=0,"-",#REF!) -> #REF! | ES6: =C6 -> #REF! | ET6: BEGINNING of the school year for STUDENTS | EU6: =IF(#REF!=0,"",#REF!) -> #REF! | EV6: =IF(OR(#REF!=0,#REF!=""),"",#REF!) -> #REF! | EW6: =EV6 -> #REF! | EZ6: =IF(#REF!=0,"",#REF!) -> #REF! | FA6: END of the school year for STUDENTS (NOT shown on graph) | FB6: =IF(#REF!=0,"",#REF!) -> #REF! | FC6: =IF(OR(#REF!=0,#REF!=""),"",#REF!) -> #REF! | FD6: =FC6 -> #REF! | FE6: - | FF6: - | FG6: =IF(#REF!=0,"-",#REF!) -> #REF! | FH6: BEGINNING of the school year for TEACHERS (NOT shown on graph) | FI6: =IF(#REF!=0,"-",#REF!) -> #REF! | FJ6: =IF(#REF!=0,"-",#REF!) -> #REF! | FK6: =IF(#REF!=0,"-",#REF!) -> #REF! | FL6: - | FM6: - | FN6: =IF(#REF!=0,"-",#REF!) -> #REF! | FO6: END of the school year for TEACHERS (NOT shown on graph) | FP6: =IF(#REF!=0,"-",#REF!) -> #REF! | FQ6: =IF(#REF!=0,"-",#REF!) -> #REF! | FR6: =IF(#REF!=0,"-",#REF!) -> #REF! | FS6: - | FT6: - | FU6: =IF(#REF!=0,"-",#REF!) -> #REF!
A7: =#REF! -> #REF! | B7: =B6 -> Country_code | C7: {=MID(CELL("filename",#REF!),FIND("]",CELL("filename",#REF!))+1,255)} -> #REF! | D7: =#REF! -> #REF! | E7: =#REF! -> #REF! | F7: =IF(#REF!=0,"-",#REF!) -> #REF! | G7: =IF(#REF!=0,"-",#REF!) -> #REF! | H7: =IF(#REF!=0,"-",#REF!) -> #REF! | I7: =IF(#REF!=0,"-",#REF!) -> #REF! | J7: =IF(#REF!=0,"-",#REF!) -> #REF! | K7: =IF(#REF!=0,"-",#REF!) -> #REF! | L7: Period 2 | M7: =IF(#REF!=0,"-",#REF!) -> #REF! | N7: =IF(#REF!=0,"-",#REF!) -> #REF! | O7: =IF(#REF!=0,"-",#REF!) -> #REF! | P7: =IF(#REF!=0,"-",#REF!) -> #REF! | Q7: =IF(#REF!=0,"-",#REF!) -> #REF! | R7: =IF(#REF!=0,"-",#REF!) -> #REF! | S7: Period 3 | T7: =IF(#REF!=0,"-",#REF!) -> #REF! | U7: =IF(#REF!=0,"-",#REF!) -> #REF! | V7: =IF(#REF!=0,"-",#REF!) -> #REF! | W7: =IF(#REF!=0,"-",#REF!) -> #REF! | X7: =IF(#REF!=0,"-",#REF!) -> #REF! | Y7: =IF(#REF!=0,"-",#REF!) -> #REF! | Z7: Period 4 | AA7: =IF(#REF!=0,"-",#REF!) -> #REF! | AB7: =IF(#REF!=0,"-",#REF!) -> #REF! | AC7: =IF(#REF!=0,"-",#REF!) -> #REF! | AD7: =IF(#REF!=0,"-",#REF!) -> #REF! | AE7: =IF(#REF!=0,"-",#REF!) -> #REF! | AF7: =IF(#REF!=0,"-",#REF!) -> #REF! | AG7: Period 5 | AH7: =IF(#REF!=0,"-",#REF!) -> #REF! | AI7: =IF(#REF!=0,"-",#REF!) -> #REF! | AJ7: =IF(#REF!=0,"-",#REF!) -> #REF! | AK7: =IF(#REF!=0,"-",#REF!) -> #REF! | AL7: =IF(#REF!=0,"-",#REF!) -> #REF! | AM7: =IF(#REF!=0,"-",#REF!) -> #REF! | AN7: Period 6 | AO7: =IF(#REF!=0,"-",#REF!) -> #REF! | AP7: =IF(#REF!=0,"-",#REF!) -> #REF! | AQ7: =IF(#REF!=0,"-",#REF!) -> #REF! | AR7: =IF(#REF!=0,"-",#REF!) -> #REF! | AS7: =IF(#REF!=0,"-",#REF!) -> #REF! | AT7: =IF(#REF!=0,"-",#REF!) -> #REF! | AU7: Period 7 | AV7: =IF(#REF!=0,"-",#REF!) -> #REF! | AW7: =IF(#REF!=0,"-",#REF!) -> #REF! | AX7: =IF(#REF!=0,"-",#REF!) -> #REF! | AY7: =IF(#REF!=0,"-",#REF!) -> #REF! | AZ7: =IF(#REF!=0,"-",#REF!) -> #REF! | BA7: =IF(#REF!=0,"-",#REF!) -> #REF! | BB7: Period 8 | BC7: =IF(#REF!=0,"-",#REF!) -> #REF! | BD7: =IF(#REF!=0,"-",#REF!) -> #REF! | BE7: =IF(#REF!=0,"-",#REF!) -> #REF! | BF7: =IF(#REF!=0,"-",#REF!) -> #REF! | BG7: =IF(#REF!=0,"-",#REF!) -> #REF! | BH7: =IF(#REF!=0,"-",#REF!) -> #REF! | BI7: Period 9 | BJ7: =IF(#REF!=0,"-",#REF!) -> #REF! | BK7: =IF(#REF!=0,"-",#REF!) -> #REF! | BL7: =IF(#REF!=0,"-",#REF!) -> #REF! | BM7: =IF(#REF!=0,"-",#REF!) -> #REF! | BN7: =IF(#REF!=0,"-",#REF!) -> #REF! | BO7: =IF(#REF!=0,"-",#REF!) -> #REF! | BP7: Period 10 | BQ7: =IF(#REF!=0,"-",#REF!) -> #REF! | BR7: =IF(#REF!="-",0,#REF!) -> #REF! | BS7: =IF(#REF!=0,"-",#REF!) -> #REF! | BT7: =IF(#REF!=0,"-",#REF!) -> #REF! | BU7: =IF(#REF!=0,"-",#REF!) -> #REF! | BV7: =IF(#REF!=0,"-",#REF!) -> #REF! | BW7: Period 11 | BX7: =IF(#REF!=0,"-",#REF!) -> #REF! | BY7: =IF(#REF!=0,"-",#REF!) -> #REF! | BZ7: =IF(#REF!=0,"-",#REF!) -> #REF! | CA7: =IF(#REF!=0,"-",#REF!) -> #REF! | CB7: =IF(#REF!=0,"-",#REF!) -> #REF! | CC7: =IF(#REF!=0,"-",#REF!) -> #REF! | CD7: Period 12 | CE7: =IF(#REF!=0,"-",#REF!) -> #REF! | CF7: =IF(#REF!=0,"-",#REF!) -> #REF! | CG7: =IF(#REF!=0,"-",#REF!) -> #REF! | CH7: =IF(#REF!=0,"-",#REF!) -> #REF! | CI7: =IF(#REF!=0,"-",#REF!) -> #REF! | CJ7: =IF(#REF!=0,"-",#REF!) -> #REF! | CK7: Period 13 | CL7: =IF(#REF!=0,"-",#REF!) -> #REF! | CM7: =IF(#REF!=0,"-",#REF!) -> #REF! | CN7: =IF(#REF!=0,"-",#REF!) -> #REF! | CO7: =IF(#REF!=0,"-",#REF!) -> #REF! | CP7: =IF(#REF!=0,"-",#REF!) -> #REF! | CQ7: =IF(#REF!=0,"-",#REF!) -> #REF! | CR7: Period 14 | CS7: =IF(#REF!=0,"-",#REF!) -> #REF! | CT7: =IF(#REF!=0,"-",#REF!) -> #REF! | CU7: =IF(#REF!=0,"-",#REF!) -> #REF! | CV7: =IF(#REF!=0,"-",#REF!) -> #REF! | CW7: =IF(#REF!=0,"-",#REF!) -> #REF! | CX7: =IF(#REF!=0,"-",#REF!) -> #REF! | CY7: Period 15 | CZ7: =IF(#REF!=0,"-",#REF!) -> #REF! | DA7: =IF(#REF!=0,"-",#REF!) -> #REF! | DB7: =IF(#REF!=0,"-",#REF!) -> #REF! | DC7: =IF(#REF!=0,"-",#REF!) -> #REF! | DD7: =IF(#REF!=0,"-",#REF!) -> #REF! | DE7: =IF(#REF!=0,"-",#REF!) -> #REF! | DF7: Period 16 | DG7: =IF(#REF!=0,"-",#REF!) -> #REF! | DH7: =IF(#REF!=0,"-",#REF!) -> #REF! | DI7: =IF(#REF!=0,"-",#REF!) -> #REF! | DJ7: =IF(#REF!=0,"-",#REF!) -> #REF! | DK7: =IF(#REF!=0,"-",#REF!) -> #REF! | DL7: =IF(#REF!=0,"-",#REF!) -> #REF! | DM7: Period 17 | DN7: =IF(#REF!=0,"-",#REF!) -> #REF! | DO7: =IF(#REF!=0,"-",#REF!) -> #REF! | DP7: =IF(#REF!=0,"-",#REF!) -> #REF! | DQ7: =IF(#REF!=0,"-",#REF!) -> #REF! | DR7: =IF(#REF!=0,"-",#REF!) -> #REF! | DS7: =IF(#REF!=0,"-",#REF!) -> #REF! | DT7: Period 18 | DU7: =IF(#REF!=0,"-",#REF!) -> #REF! | DV7: =IF(#REF!=0,"-",#REF!) -> #REF! | DW7: =IF(#REF!=0,"-",#REF!) -> #REF! | DX7: =IF(#REF!=0,"-",#REF!) -> #REF! | DY7: =IF(#REF!=0,"-",#REF!) -> #REF! | DZ7: =IF(#REF!=0,"-",#REF!) -> #REF! | EA7: Period 19 | EB7: =IF(#REF!=0,"-",#REF!) -> #REF! | EC7: =IF(#REF!=0,"-",#REF!) -> #REF! | ED7: =IF(#REF!=0,"-",#REF!) -> #REF! | EE7: =IF(#REF!=0,"-",#REF!) -> #REF! | EF7: =IF(#REF!=0,"-",#REF!) -> #REF! | EG7: =IF(#REF!=0,"-",#REF!) -> #REF! | EH7: Period 20 | EI7: =IF(#REF!=0,"-",#REF!) -> #REF! | EJ7: =IF(#REF!=0,"-",#REF!) -> #REF! | EK7: =IF(#REF!=0,"-",#REF!) -> #REF! | EL7: =IF(#REF!=0,"-",#REF!) -> #REF! | EM7: =IF(#REF!=0,"-",#REF!) -> #REF! | EN7: =IF(#REF!=0,"-",#REF!) -> #REF! | ES7: =C7 -> #REF! | ET7: BEGINNING of the school year for STUDENTS | EU7: =IF(#REF!=0,"",#REF!) -> #REF! | EV7: =IF(OR(#REF!=0,#REF!=""),"",#REF!) -> #REF! | EW7: =EV7 -> #REF! | EZ7: =IF(#REF!=0,"",#REF!) -> #REF! | FA7: END of the school year for STUDENTS (NOT shown on graph) | FB7: =IF(#REF!=0,"",#REF!) -> #REF! | FC7: =IF(OR(#REF!=0,#REF!=""),"",#REF!) -> #REF! | FD7: =FC7 -> #REF! | FE7: - | FF7: - | FG7: =IF(#REF!=0,"-",#REF!) -> #REF! | FH7: BEGINNING of the school year for TEACHERS (NOT shown on graph) | FI7: =IF(#REF!=0,"-",#REF!) -> #REF! | FJ7: =IF(#REF!=0,"-",#REF!) -> #REF! | FK7: =IF(#REF!=0,"-",#REF!) -> #REF! | FL7: - | FM7: - | FN7: =IF(#REF!=0,"-",#REF!) -> #REF! | FO7: END of the school year for TEACHERS (NOT shown on graph) | FP7: =IF(#REF!=0,"-",#REF!) -> #REF! | FQ7: =IF(#REF!=0,"-",#REF!) -> #REF! | FR7: =IF(#REF!=0,"-",#REF!) -> #REF! | FS7: - | FT7: - | FU7: =IF(#REF!=0,"-",#REF!) -> #REF!
A8: =#REF! -> #REF! | B8: =B7 -> Country_code | C8: {=MID(CELL("filename",#REF!),FIND("]",CELL("filename",#REF!))+1,255)} -> #REF! | D8: =#REF! -> #REF! | E8: =#REF! -> #REF! | F8: =IF(#REF!=0,"-",#REF!) -> #REF! | G8: =IF(#REF!=0,"-",#REF!) -> #REF! | H8: =IF(#REF!=0,"-",#REF!) -> #REF! | I8: =IF(#REF!=0,"-",#REF!) -> #REF! | J8: =IF(#REF!=0,"-",#REF!) -> #REF! | K8: =IF(#REF!=0,"-",#REF!) -> #REF! | L8: Period 2 | M8: =IF(#REF!=0,"-",#REF!) -> #REF! | N8: =IF(#REF!=0,"-",#REF!) -> #REF! | O8: =IF(#REF!=0,"-",#REF!) -> #REF! | P8: =IF(#REF!=0,"-",#REF!) -> #REF! | Q8: =IF(#REF!=0,"-",#REF!) -> #REF! | R8: =IF(#REF!=0,"-",#REF!) -> #REF! | S8: Period 3 | T8: =IF(#REF!=0,"-",#REF!) -> #REF! | U8: =IF(#REF!=0,"-",#REF!) -> #REF! | V8: =IF(#REF!=0,"-",#REF!) -> #REF! | W8: =IF(#REF!=0,"-",#REF!) -> #REF! | X8: =IF(#REF!=0,"-",#REF!) -> #REF! | Y8: =IF(#REF!=0,"-",#REF!) -> #REF! | Z8: Period 4 | AA8: =IF(#REF!=0,"-",#REF!) -> #REF! | AB8: =IF(#REF!=0,"-",#REF!) -> #REF! | AC8: =IF(#REF!=0,"-",#REF!) -> #REF! | AD8: =IF(#REF!=0,"-",#REF!) -> #REF! | AE8: =IF(#REF!=0,"-",#REF!) -> #REF! | AF8: =IF(#REF!=0,"-",#REF!) -> #REF! | AG8: Period 5 | AH8: =IF(#REF!=0,"-",#REF!) -> #REF! | AI8: =IF(#REF!=0,"-",#REF!) -> #REF! | AJ8: =IF(#REF!=0,"-",#REF!) -> #REF! | AK8: =IF(#REF!=0,"-",#REF!) -> #REF! | AL8: =IF(#REF!=0,"-",#REF!) -> #REF! | AM8: =IF(#REF!=0,"-",#REF!) -> #REF! | AN8: Period 6 | AO8: =IF(#REF!=0,"-",#REF!) -> #REF! | AP8: =IF(#REF!=0,"-",#REF!) -> #REF! | AQ8: =IF(#REF!=0,"-",#REF!) -> #REF! | AR8: =IF(#REF!=0,"-",#REF!) -> #REF! | AS8: =IF(#REF!=0,"-",#REF!) -> #REF! | AT8: =IF(#REF!=0,"-",#REF!) -> #REF! | AU8: Period 7 | AV8: =IF(#REF!=0,"-",#REF!) -> #REF! | AW8: =IF(#REF!=0,"-",#REF!) -> #REF! | AX8: =IF(#REF!=0,"-",#REF!) -> #REF! | AY8: =IF(#REF!=0,"-",#REF!) -> #REF! | AZ8: =IF(#REF!=0,"-",#REF!) -> #REF! | BA8: =IF(#REF!=0,"-",#REF!) -> #REF! | BB8: Period 8 | BC8: =IF(#REF!=0,"-",#REF!) -> #REF! | BD8: =IF(#REF!=0,"-",#REF!) -> #REF! | BE8: =IF(#REF!=0,"-",#REF!) -> #REF! | BF8: =IF(#REF!=0,"-",#REF!) -> #REF! | BG8: =IF(#REF!=0,"-",#REF!) -> #REF! | BH8: =IF(#REF!=0,"-",#REF!) -> #REF! | BI8: Period 9 | BJ8: =IF(#REF!=0,"-",#REF!) -> #REF! | BK8: =IF(#REF!=0,"-",#REF!) -> #REF! | BL8: =IF(#REF!=0,"-",#REF!) -> #REF! | BM8: =IF(#REF!=0,"-",#REF!) -> #REF! | BN8: =IF(#REF!=0,"-",#REF!) -> #REF! | BO8: =IF(#REF!=0,"-",#REF!) -> #REF! | BP8: Period 10 | BQ8: =IF(#REF!=0,"-",#REF!) -> #REF! | BR8: =IF(#REF!="-",0,#REF!) -> #REF! | BS8: =IF(#REF!=0,"-",#REF!) -> #REF! | BT8: =IF(#REF!=0,"-",#REF!) -> #REF! | BU8: =IF(#REF!=0,"-",#REF!) -> #REF! | BV8: =IF(#REF!=0,"-",#REF!) -> #REF! | BW8: Period 11 | BX8: =IF(#REF!=0,"-",#REF!) -> #REF! | BY8: =IF(#REF!=0,"-",#REF!) -> #REF! | BZ8: =IF(#REF!=0,"-",#REF!) -> #REF! | CA8: =IF(#REF!=0,"-",#REF!) -> #REF! | CB8: =IF(#REF!=0,"-",#REF!) -> #REF! | CC8: =IF(#REF!=0,"-",#REF!) -> #REF! | CD8: Period 12 | CE8: =IF(#REF!=0,"-",#REF!) -> #REF! | CF8: =IF(#REF!=0,"-",#REF!) -> #REF! | CG8: =IF(#REF!=0,"-",#REF!) -> #REF! | CH8: =IF(#REF!=0,"-",#REF!) -> #REF! | CI8: =IF(#REF!=0,"-",#REF!) -> #REF! | CJ8: =IF(#REF!=0,"-",#REF!) -> #REF! | CK8: Period 13 | CL8: =IF(#REF!=0,"-",#REF!) -> #REF! | CM8: =IF(#REF!=0,"-",#REF!) -> #REF! | CN8: =IF(#REF!=0,"-",#REF!) -> #REF! | CO8: =IF(#REF!=0,"-",#REF!) -> #REF! | CP8: =IF(#REF!=0,"-",#REF!) -> #REF! | CQ8: =IF(#REF!=0,"-",#REF!) -> #REF! | CR8: Period 14 | CS8: =IF(#REF!=0,"-",#REF!) -> #REF! | CT8: =IF(#REF!=0,"-",#REF!) -> #REF! | CU8: =IF(#REF!=0,"-",#REF!) -> #REF! | CV8: =IF(#REF!=0,"-",#REF!) -> #REF! | CW8: =IF(#REF!=0,"-",#REF!) -> #REF! | CX8: =IF(#REF!=0,"-",#REF!) -> #REF! | CY8: Period 15 | CZ8: =IF(#REF!=0,"-",#REF!) -> #REF! | DA8: =IF(#REF!=0,"-",#REF!) -> #REF! | DB8: =IF(#REF!=0,"-",#REF!) -> #REF! | DC8: =IF(#REF!=0,"-",#REF!) -> #REF! | DD8: =IF(#REF!=0,"-",#REF!) -> #REF! | DE8: =IF(#REF!=0,"-",#REF!) -> #REF! | DF8: Period 16 | DG8: =IF(#REF!=0,"-",#REF!) -> #REF! | DH8: =IF(#REF!=0,"-",#REF!) -> #REF! | DI8: =IF(#REF!=0,"-",#REF!) -> #REF! | DJ8: =IF(#REF!=0,"-",#REF!) -> #REF! | DK8: =IF(#REF!=0,"-",#REF!) -> #REF! | DL8: =IF(#REF!=0,"-",#REF!) -> #REF! | DM8: Period 17 | DN8: =IF(#REF!=0,"-",#REF!) -> #REF! | DO8: =IF(#REF!=0,"-",#REF!) -> #REF! | DP8: =IF(#REF!=0,"-",#REF!) -> #REF! | DQ8: =IF(#REF!=0,"-",#REF!) -> #REF! | DR8: =IF(#REF!=0,"-",#REF!) -> #REF! | DS8: =IF(#REF!=0,"-",#REF!) -> #REF! | DT8: Period 18 | DU8: =IF(#REF!=0,"-",#REF!) -> #REF! | DV8: =IF(#REF!=0,"-",#REF!) -> #REF! | DW8: =IF(#REF!=0,"-",#REF!) -> #REF! | DX8: =IF(#REF!=0,"-",#REF!) -> #REF! | DY8: =IF(#REF!=0,"-",#REF!) -> #REF! | DZ8: =IF(#REF!=0,"-",#REF!) -> #REF! | EA8: Period 19 | EB8: =IF(#REF!=0,"-",#REF!) -> #REF! | EC8: =IF(#REF!=0,"-",#REF!) -> #REF! | ED8: =IF(#REF!=0,"-",#REF!) -> #REF! | EE8: =IF(#REF!=0,"-",#REF!) -> #REF! | EF8: =IF(#REF!=0,"-",#REF!) -> #REF! | EG8: =IF(#REF!=0,"-",#REF!) -> #REF! | EH8: Period 20 | EI8: =IF(#REF!=0,"-",#REF!) -> #REF! | EJ8: =IF(#REF!=0,"-",#REF!) -> #REF! | EK8: =IF(#REF!=0,"-",#REF!) -> #REF! | EL8: =IF(#REF!=0,"-",#REF!) -> #REF! | EM8: =IF(#REF!=0,"-",#REF!) -> #REF! | EN8: =IF(#REF!=0,"-",#REF!) -> #REF! | ES8: =C8 -> #REF! | ET8: BEGINNING of the school year for STUDENTS | EU8: =IF(#REF!=0,"",#REF!) -> #REF! | EV8: =IF(OR(#REF!=0,#REF!=""),"",#REF!) -> #REF! | EW8: =EV8 -> #REF! | EZ8: =IF(#REF!=0,"",#REF!) -> #REF! | FA8: END of the school year for STUDENTS (NOT shown on graph) | FB8: =IF(#REF!=0,"",#REF!) -> #REF! | FC8: =IF(OR(#REF!=0,#REF!=""),"",#REF!) -> #REF! | FD8: =FC8 -> #REF! | FE8: - | FF8: - | FG8: =IF(#REF!=0,"-",#REF!) -> #REF! | FH8: BEGINNING of the school year for TEACHERS (NOT shown on graph) | FI8: =IF(#REF!=0,"-",#REF!) -> #REF! | FJ8: =IF(#REF!=0,"-",#REF!) -> #REF! | FK8: =IF(#REF!=0,"-",#REF!) -> #REF! | FL8: - | FM8: - | FN8: =IF(#REF!=0,"-",#REF!) -> #REF! | FO8: END of the school year for TEACHERS (NOT shown on graph) | FP8: =IF(#REF!=0,"-",#REF!) -> #REF! | FQ8: =IF(#REF!=0,"-",#REF!) -> #REF! | FR8: =IF(#REF!=0,"-",#REF!) -> #REF! | FS8: - | FT8: - | FU8: =IF(#REF!=0,"-",#REF!) -> #REF!
A9: =#REF! -> #REF! | B9: =B8 -> Country_code | C9: {=MID(CELL("filename",#REF!),FIND("]",CELL("filename",#REF!))+1,255)} -> #REF! | D9: =#REF! -> #REF! | E9: =#REF! -> #REF! | F9: =IF(#REF!=0,"-",#REF!) -> #REF! | G9: =IF(#REF!=0,"-",#REF!) -> #REF! | H9: =IF(#REF!=0,"-",#REF!) -> #REF! | I9: =IF(#REF!=0,"-",#REF!) -> #REF! | J9: =IF(#REF!=0,"-",#REF!) -> #REF! | K9: =IF(#REF!=0,"-",#REF!) -> #REF! | L9: Period 2 | M9: =IF(#REF!=0,"-",#REF!) -> #REF! | N9: =IF(#REF!=0,"-",#REF!) -> #REF! | O9: =IF(#REF!=0,"-",#REF!) -> #REF! | P9: =IF(#REF!=0,"-",#REF!) -> #REF! | Q9: =IF(#REF!=0,"-",#REF!) -> #REF! | R9: =IF(#REF!=0,"-",#REF!) -> #REF! | S9: Period 3 | T9: =IF(#REF!=0,"-",#REF!) -> #REF! | U9: =IF(#REF!=0,"-",#REF!) -> #REF! | V9: =IF(#REF!=0,"-",#REF!) -> #REF! | W9: =IF(#REF!=0,"-",#REF!) -> #REF! | X9: =IF(#REF!=0,"-",#REF!) -> #REF! | Y9: =IF(#REF!=0,"-",#REF!) -> #REF! | Z9: Period 4 | AA9: =IF(#REF!=0,"-",#REF!) -> #REF! | AB9: =IF(#REF!=0,"-",#REF!) -> #REF! | AC9: =IF(#REF!=0,"-",#REF!) -> #REF! | AD9: =IF(#REF!=0,"-",#REF!) -> #REF! | AE9: =IF(#REF!=0,"-",#REF!) -> #REF! | AF9: =IF(#REF!=0,"-",#REF!) -> #REF! | AG9: Period 5 | AH9: =IF(#REF!=0,"-",#REF!) -> #REF! | AI9: =IF(#REF!=0,"-",#REF!) -> #REF! | AJ9: =IF(#REF!=0,"-",#REF!) -> #REF! | AK9: =IF(#REF!=0,"-",#REF!) -> #REF! | AL9: =IF(#REF!=0,"-",#REF!) -> #REF! | AM9: =IF(#REF!=0,"-",#REF!) -> #REF! | AN9: Period 6 | AO9: =IF(#REF!=0,"-",#REF!) -> #REF! | AP9: =IF(#REF!=0,"-",#REF!) -> #REF! | AQ9: =IF(#REF!=0,"-",#REF!) -> #REF! | AR9: =IF(#REF!=0,"-",#REF!) -> #REF! | AS9: =IF(#REF!=0,"-",#REF!) -> #REF! | AT9: =IF(#REF!=0,"-",#REF!) -> #REF! | AU9: Period 7 | AV9: =IF(#REF!=0,"-",#REF!) -> #REF! | AW9: =IF(#REF!=0,"-",#REF!) -> #REF! | AX9: =IF(#REF!=0,"-",#REF!) -> #REF! | AY9: =IF(#REF!=0,"-",#REF!) -> #REF! | AZ9: =IF(#REF!=0,"-",#REF!) -> #REF! | BA9: =IF(#REF!=0,"-",#REF!) -> #REF! | BB9: Period 8 | BC9: =IF(#REF!=0,"-",#REF!) -> #REF! | BD9: =IF(#REF!=0,"-",#REF!) -> #REF! | BE9: =IF(#REF!=0,"-",#REF!) -> #REF! | BF9: =IF(#REF!=0,"-",#REF!) -> #REF! | BG9: =IF(#REF!=0,"-",#REF!) -> #REF! | BH9: =IF(#REF!=0,"-",#REF!) -> #REF! | BI9: Period 9 | BJ9: =IF(#REF!=0,"-",#REF!) -> #REF! | BK9: =IF(#REF!=0,"-",#REF!) -> #REF! | BL9: =IF(#REF!=0,"-",#REF!) -> #REF! | BM9: =IF(#REF!=0,"-",#REF!) -> #REF! | BN9: =IF(#REF!=0,"-",#REF!) -> #REF! | BO9: =IF(#REF!=0,"-",#REF!) -> #REF! | BP9: Period 10 | BQ9: =IF(#REF!=0,"-",#REF!) -> #REF! | BR9: =IF(#REF!="-",0,#REF!) -> #REF! | BS9: =IF(#REF!=0,"-",#REF!) -> #REF! | BT9: =IF(#REF!=0,"-",#REF!) -> #REF! | BU9: =IF(#REF!=0,"-",#REF!) -> #REF! | BV9: =IF(#REF!=0,"-",#REF!) -> #REF! | BW9: Period 11 | BX9: =IF(#REF!=0,"-",#REF!) -> #REF! | BY9: =IF(#REF!=0,"-",#REF!) -> #REF! | BZ9: =IF(#REF!=0,"-",#REF!) -> #REF! | CA9: =IF(#REF!=0,"-",#REF!) -> #REF! | CB9: =IF(#REF!=0,"-",#REF!) -> #REF! | CC9: =IF(#REF!=0,"-",#REF!) -> #REF! | CD9: Period 12 | CE9: =IF(#REF!=0,"-",#REF!) -> #REF! | CF9: =IF(#REF!=0,"-",#REF!) -> #REF! | CG9: =IF(#REF!=0,"-",#REF!) -> #REF! | CH9: =IF(#REF!=0,"-",#REF!) -> #REF! | CI9: =IF(#REF!=0,"-",#REF!) -> #REF! | CJ9: =IF(#REF!=0,"-",#REF!) -> #REF! | CK9: Period 13 | CL9: =IF(#REF!=0,"-",#REF!) -> #REF! | CM9: =IF(#REF!=0,"-",#REF!) -> #REF! | CN9: =IF(#REF!=0,"-",#REF!) -> #REF! | CO9: =IF(#REF!=0,"-",#REF!) -> #REF! | CP9: =IF(#REF!=0,"-",#REF!) -> #REF! | CQ9: =IF(#REF!=0,"-",#REF!) -> #REF! | CR9: Period 14 | CS9: =IF(#REF!=0,"-",#REF!) -> #REF! | CT9: =IF(#REF!=0,"-",#REF!) -> #REF! | CU9: =IF(#REF!=0,"-",#REF!) -> #REF! | CV9: =IF(#REF!=0,"-",#REF!) -> #REF! | CW9: =IF(#REF!=0,"-",#REF!) -> #REF! | CX9: =IF(#REF!=0,"-",#REF!) -> #REF! | CY9: Period 15 | CZ9: =IF(#REF!=0,"-",#REF!) -> #REF! | DA9: =IF(#REF!=0,"-",#REF!) -> #REF! | DB9: =IF(#REF!=0,"-",#REF!) -> #REF! | DC9: =IF(#REF!=0,"-",#REF!) -> #REF! | DD9: =IF(#REF!=0,"-",#REF!) -> #REF! | DE9: =IF(#REF!=0,"-",#REF!) -> #REF! | DF9: Period 16 | DG9: =IF(#REF!=0,"-",#REF!) -> #REF! | DH9: =IF(#REF!=0,"-",#REF!) -> #REF! | DI9: =IF(#REF!=0,"-",#REF!) -> #REF! | DJ9: =IF(#REF!=0,"-",#REF!) -> #REF! | DK9: =IF(#REF!=0,"-",#REF!) -> #REF! | DL9: =IF(#REF!=0,"-",#REF!) -> #REF! | DM9: Period 17 | DN9: =IF(#REF!=0,"-",#REF!) -> #REF! | DO9: =IF(#REF!=0,"-",#REF!) -> #REF! | DP9: =IF(#REF!=0,"-",#REF!) -> #REF! | DQ9: =IF(#REF!=0,"-",#REF!) -> #REF! | DR9: =IF(#REF!=0,"-",#REF!) -> #REF! | DS9: =IF(#REF!=0,"-",#REF!) -> #REF! | DT9: Period 18 | DU9: =IF(#REF!=0,"-",#REF!) -> #REF! | DV9: =IF(#REF!=0,"-",#REF!) -> #REF! | DW9: =IF(#REF!=0,"-",#REF!) -> #REF! | DX9: =IF(#REF!=0,"-",#REF!) -> #REF! | DY9: =IF(#REF!=0,"-",#REF!) -> #REF! | DZ9: =IF(#REF!=0,"-",#REF!) -> #REF! | EA9: Period 19 | EB9: =IF(#REF!=0,"-",#REF!) -> #REF! | EC9: =IF(#REF!=0,"-",#REF!) -> #REF! | ED9: =IF(#REF!=0,"-",#REF!) -> #REF! | EE9: =IF(#REF!=0,"-",#REF!) -> #REF! | EF9: =IF(#REF!=0,"-",#REF!) -> #REF! | EG9: =IF(#REF!=0,"-",#REF!) -> #REF! | EH9: Period 20 | EI9: =IF(#REF!=0,"-",#REF!) -> #REF! | EJ9: =IF(#REF!=0,"-",#REF!) -> #REF! | EK9: =IF(#REF!=0,"-",#REF!) -> #REF! | EL9: =IF(#REF!=0,"-",#REF!) -> #REF! | EM9: =IF(#REF!=0,"-",#REF!) -> #REF! | EN9: =IF(#REF!=0,"-",#REF!) -> #REF! | ES9: =C9 -> #REF! | ET9: BEGINNING of the school year for STUDENTS | EU9: =IF(#REF!=0,"",#REF!) -> #REF! | EV9: =IF(OR(#REF!=0,#REF!=""),"",#REF!) -> #REF! | EW9: =EV9 -> #REF! | EZ9: =IF(#REF!=0,"",#REF!) -> #REF! | FA9: END of the school year for STUDENTS (NOT shown on graph) | FB9: =IF(#REF!=0,"",#REF!) -> #REF! | FC9: =IF(OR(#REF!=0,#REF!=""),"",#REF!) -> #REF! | FD9: =FC9 -> #REF! | FE9: - | FF9: - | FG9: =IF(#REF!=0,"-",#REF!) -> #REF! | FH9: BEGINNING of the school year for TEACHERS (NOT shown on graph) | FI9: =IF(#REF!=0,"-",#REF!) -> #REF! | FJ9: =IF(#REF!=0,"-",#REF!) -> #REF! | FK9: =IF(#REF!=0,"-",#REF!) -> #REF! | FL9: - | FM9: - | FN9: =IF(#REF!=0,"-",#REF!) -> #REF! | FO9: END of the school year for TEACHERS (NOT shown on graph) | FP9: =IF(#REF!=0,"-",#REF!) -> #REF! | FQ9: =IF(#REF!=0,"-",#REF!) -> #REF! | FR9: =IF(#REF!=0,"-",#REF!) -> #REF! | FS9: - | FT9: - | FU9: =IF(#REF!=0,"-",#REF!) -> #REF!
A10: =#REF! -> #REF! | B10: =B9 -> Country_code | C10: {=MID(CELL("filename",#REF!),FIND("]",CELL("filename",#REF!))+1,255)} -> #REF! | D10: =#REF! -> #REF! | E10: =#REF! -> #REF! | F10: =IF(#REF!=0,"-",#REF!) -> #REF! | G10: =IF(#REF!=0,"-",#REF!) -> #REF! | H10: =IF(#REF!=0,"-",#REF!) -> #REF! | I10: =IF(#REF!=0,"-",#REF!) -> #REF! | J10: =IF(#REF!=0,"-",#REF!) -> #REF! | K10: =IF(#REF!=0,"-",#REF!) -> #REF! | L10: Period 2 | M10: =IF(#REF!=0,"-",#REF!) -> #REF! | N10: =IF(#REF!=0,"-",#REF!) -> #REF! | O10: =IF(#REF!=0,"-",#REF!) -> #REF! | P10: =IF(#REF!=0,"-",#REF!) -> #REF! | Q10: =IF(#REF!=0,"-",#REF!) -> #REF! | R10: =IF(#REF!=0,"-",#REF!) -> #REF! | S10: Period 3 | T10: =IF(#REF!=0,"-",#REF!) -> #REF! | U10: =IF(#REF!=0,"-",#REF!) -> #REF! | V10: =IF(#REF!=0,"-",#REF!) -> #REF! | W10: =IF(#REF!=0,"-",#REF!) -> #REF! | X10: =IF(#REF!=0,"-",#REF!) -> #REF! | Y10: =IF(#REF!=0,"-",#REF!) -> #REF! | Z10: Period 4 | AA10: =IF(#REF!=0,"-",#REF!) -> #REF! | AB10: =IF(#REF!=0,"-",#REF!) -> #REF! | AC10: =IF(#REF!=0,"-",#REF!) -> #REF! | AD10: =IF(#REF!=0,"-",#REF!) -> #REF! | AE10: =IF(#REF!=0,"-",#REF!) -> #REF! | AF10: =IF(#REF!=0,"-",#REF!) -> #REF! | AG10: Period 5 | AH10: =IF(#REF!=0,"-",#REF!) -> #REF! | AI10: =IF(#REF!=0,"-",#REF!) -> #REF! | AJ10: =IF(#REF!=0,"-",#REF!) -> #REF! | AK10: =IF(#REF!=0,"-",#REF!) -> #REF! | AL10: =IF(#REF!=0,"-",#REF!) -> #REF! | AM10: =IF(#REF!=0,"-",#REF!) -> #REF! | AN10: Period 6 | AO10: =IF(#REF!=0,"-",#REF!) -> #REF! | AP10: =IF(#REF!=0,"-",#REF!) -> #REF! | AQ10: =IF(#REF!=0,"-",#REF!) -> #REF! | AR10: =IF(#REF!=0,"-",#REF!) -> #REF! | AS10: =IF(#REF!=0,"-",#REF!) -> #REF! | AT10: =IF(#REF!=0,"-",#REF!) -> #REF! | AU10: Period 7 | AV10: =IF(#REF!=0,"-",#REF!) -> #REF! | AW10: =IF(#REF!=0,"-",#REF!) -> #REF! | AX10: =IF(#REF!=0,"-",#REF!) -> #REF! | AY10: =IF(#REF!=0,"-",#REF!) -> #REF! | AZ10: =IF(#REF!=0,"-",#REF!) -> #REF! | BA10: =IF(#REF!=0,"-",#REF!) -> #REF! | BB10: Period 8 | BC10: =IF(#REF!=0,"-",#REF!) -> #REF! | BD10: =IF(#REF!=0,"-",#REF!) -> #REF! | BE10: =IF(#REF!=0,"-",#REF!) -> #REF! | BF10: =IF(#REF!=0,"-",#REF!) -> #REF! | BG10: =IF(#REF!=0,"-",#REF!) -> #REF! | BH10: =IF(#REF!=0,"-",#REF!) -> #REF! | BI10: Period 9 | BJ10: =IF(#REF!=0,"-",#REF!) -> #REF! | BK10: =IF(#REF!=0,"-",#REF!) -> #REF! | BL10: =IF(#REF!=0,"-",#REF!) -> #REF! | BM10: =IF(#REF!=0,"-",#REF!) -> #REF! | BN10: =IF(#REF!=0,"-",#REF!) -> #REF! | BO10: =IF(#REF!=0,"-",#REF!) -> #REF! | BP10: Period 10 | BQ10: =IF(#REF!=0,"-",#REF!) -> #REF! | BR10: =IF(#REF!="-",0,#REF!) -> #REF! | BS10: =IF(#REF!=0,"-",#REF!) -> #REF! | BT10: =IF(#REF!=0,"-",#REF!) -> #REF! | BU10: =IF(#REF!=0,"-",#REF!) -> #REF! | BV10: =IF(#REF!=0,"-",#REF!) -> #REF! | BW10: Period 11 | BX10: =IF(#REF!=0,"-",#REF!) -> #REF! | BY10: =IF(#REF!=0,"-",#REF!) -> #REF! | BZ10: =IF(#REF!=0,"-",#REF!) -> #REF! | CA10: =IF(#REF!=0,"-",#REF!) -> #REF! | CB10: =IF(#REF!=0,"-",#REF!) -> #REF! | CC10: =IF(#REF!=0,"-",#REF!) -> #REF! | CD10: Period 12 | CE10: =IF(#REF!=0,"-",#REF!) -> #REF! | CF10: =IF(#REF!=0,"-",#REF!) -> #REF! | CG10: =IF(#REF!=0,"-",#REF!) -> #REF! | CH10: =IF(#REF!=0,"-",#REF!) -> #REF! | CI10: =IF(#REF!=0,"-",#REF!) -> #REF! | CJ10: =IF(#REF!=0,"-",#REF!) -> #REF! | CK10: Period 13 | CL10: =IF(#REF!=0,"-",#REF!) -> #REF! | CM10: =IF(#REF!=0,"-",#REF!) -> #REF! | CN10: =IF(#REF!=0,"-",#REF!) -> #REF! | CO10: =IF(#REF!=0,"-",#REF!) -> #REF! | CP10: =IF(#REF!=0,"-",#REF!) -> #REF! | CQ10: =IF(#REF!=0,"-",#REF!) -> #REF! | CR10: Period 14 | CS10: =IF(#REF!=0,"-",#REF!) -> #REF! | CT10: =IF(#REF!=0,"-",#REF!) -> #REF! | CU10: =IF(#REF!=0,"-",#REF!) -> #REF! | CV10: =IF(#REF!=0,"-",#REF!) -> #REF! | CW10: =IF(#REF!=0,"-",#REF!) -> #REF! | CX10: =IF(#REF!=0,"-",#REF!) -> #REF! | CY10: Period 15 | CZ10: =IF(#REF!=0,"-",#REF!) -> #REF! | DA10: =IF(#REF!=0,"-",#REF!) -> #REF! | DB10: =IF(#REF!=0,"-",#REF!) -> #REF! | DC10: =IF(#REF!=0,"-",#REF!) -> #REF! | DD10: =IF(#REF!=0,"-",#REF!) -> #REF! | DE10: =IF(#REF!=0,"-",#REF!) -> #REF! | DF10: Period 16 | DG10: =IF(#REF!=0,"-",#REF!) -> #REF! | DH10: =IF(#REF!=0,"-",#REF!) -> #REF! | DI10: =IF(#REF!=0,"-",#REF!) -> #REF! | DJ10: =IF(#REF!=0,"-",#REF!) -> #REF! | DK10: =IF(#REF!=0,"-",#REF!) -> #REF! | DL10: =IF(#REF!=0,"-",#REF!) -> #REF! | DM10: Period 17 | DN10: =IF(#REF!=0,"-",#REF!) -> #REF! | DO10: =IF(#REF!=0,"-",#REF!) -> #REF! | DP10: =IF(#REF!=0,"-",#REF!) -> #REF! | DQ10: =IF(#REF!=0,"-",#REF!) -> #REF! | DR10: =IF(#REF!=0,"-",#REF!) -> #REF! | DS10: =IF(#REF!=0,"-",#REF!) -> #REF! | DT10: Period 18 | DU10: =IF(#REF!=0,"-",#REF!) -> #REF! | DV10: =IF(#REF!=0,"-",#REF!) -> #REF! | DW10: =IF(#REF!=0,"-",#REF!) -> #REF! | DX10: =IF(#REF!=0,"-",#REF!) -> #REF! | DY10: =IF(#REF!=0,"-",#REF!) -> #REF! | DZ10: =IF(#REF!=0,"-",#REF!) -> #REF! | EA10: Period 19 | EB10: =IF(#REF!=0,"-",#REF!) -> #REF! | EC10: =IF(#REF!=0,"-",#REF!) -> #REF! | ED10: =IF(#REF!=0,"-",#REF!) -> #REF! | EE10: =IF(#REF!=0,"-",#REF!) -> #REF! | EF10: =IF(#REF!=0,"-",#REF!) -> #REF! | EG10: =IF(#REF!=0,"-",#REF!) -> #REF! | EH10: Period 20 | EI10: =IF(#REF!=0,"-",#REF!) -> #REF! | EJ10: =IF(#REF!=0,"-",#REF!) -> #REF! | EK10: =IF(#REF!=0,"-",#REF!) -> #REF! | EL10: =IF(#REF!=0,"-",#REF!) -> #REF! | EM10: =IF(#REF!=0,"-",#REF!) -> #REF! | EN10: =IF(#REF!=0,"-",#REF!) -> #REF! | ES10: =C10 -> #REF! | ET10: BEGINNING of the school year for STUDENTS | EU10: =IF(#REF!=0,"",#REF!) -> #REF! | EV10: =IF(OR(#REF!=0,#REF!=""),"",#REF!) -> #REF! | EW10: =EV10 -> #REF! | EZ10: =IF(#REF!=0,"",#REF!) -> #REF! | FA10: END of the school year for STUDENTS (NOT shown on graph) | FB10: =IF(#REF!=0,"",#REF!) -> #REF! | FC10: =IF(OR(#REF!=0,#REF!=""),"",#REF!) -> #REF! | FD10: =FC10 -> #REF! | FE10: - | FF10: - | FG10: =IF(#REF!=0,"-",#REF!) -> #REF! | FH10: BEGINNING of the school year for TEACHERS (NOT shown on graph) | FI10: =IF(#REF!=0,"-",#REF!) -> #REF! | FJ10: =IF(#REF!=0,"-",#REF!) -> #REF! | FK10: =IF(#REF!=0,"-",#REF!) -> #REF! | FL10: - | FM10: - | FN10: =IF(#REF!=0,"-",#REF!) -> #REF! | FO10: END of the school year for TEACHERS (NOT shown on graph) | FP10: =IF(#REF!=0,"-",#REF!) -> #REF! | FQ10: =IF(#REF!=0,"-",#REF!) -> #REF! | FR10: =IF(#REF!=0,"-",#REF!) -> #REF! | FS10: - | FT10: - | FU10: =IF(#REF!=0,"-",#REF!) -> #REF!
